<robot name="threeJointsSnake">

  <!-- ros_control plugin -->
  <gazebo>
    <plugin name="gazebo_ros_control" filename="libgazebo_ros_control.so">
      <robotNamespace>/snake</robotNamespace>
      <robotSimType>gazebo_ros_control/DefaultRobotHWSim</robotSimType>
    </plugin>
  </gazebo>

  <material name="Blue">
    <color rgba="0.2 0.1 0.8 1.0"/>
  </material>
  <material name="Green">
    <color rgba="0.22 0.32 0.14 1.0"/>
  </material>

	<!-- attach the base_link to world -->
  <link name="world"/>

  <joint name="fixed" type="fixed">
    <parent link="world"/>
    <child link="base_link"/>
  </joint>

	<link name="base_link">
		<visual>
			<origin
				xyz="0. 0. 0."
				rpy="1.57079632679 0 1.57079632679"
			/>
			<geometry>
				<mesh
					filename="package://snake_robot/snake_description/meshes/servo.stl" scale="0.001 0.001 0.001"/>
			</geometry>
			<material name="Blue"/>
		</visual>
		
		<!-- in gazebo, there has to be a mass and an inertia for each link -->
		<inertial>
      <origin xyz="0 0 0.036" rpy="0 0 0"/>
      <mass value="1"/>
      <inertia
	  ixx="0.1" ixy="0.0" ixz="0.0"
	  iyy="0.1" iyz="0.0"
	  izz="0.1"/>
    </inertial>
	</link>

	<joint name="joint1" type="continuous">
		<origin
			xyz="0. 0. 0."
			rpy="0. 0. 0."
		/>
		<parent link="base_link"/>
		<child link="link2"/>
		<safety_controller k_position="100.0" k_velocity="40.0" soft_lower_limit="-1.5" soft_upper_limit="1.5"/>
		<limit effort="0.01" lower="-1" upper="1" velocity="0.5"/>
		<dynamics damping="0.7"/>
	</joint>

	<link name="link2">
		<visual>
			<origin
				xyz="0. 0. 0.072"
				rpy="1.57079632679 0 0."
			/>
			<geometry>
				<mesh
					filename="package://snake_robot/snake_description/meshes/servo.stl" scale="0.001 0.001 0.001"/>
			</geometry>
			<material name="Green"/>
		</visual>

		<inertial>
	    <origin xyz="0 0 0.036" rpy="0 0 0"/>
	    <mass value="1"/>
	    <inertia
		  ixx="0.1" ixy="0.0" ixz="0.0"
		  iyy="0.1" iyz="0.0"
		  izz="0.1"/>
	    </inertial>
	</link>

	<joint name="joint2" type="continuous">
		<origin
			xyz="0. 0. 0.072"
			rpy="0. 0. 1.57079632679"
		/>
		<parent link="link2"/>
		<child link="link3"/>
		<safety_controller k_position="100.0" k_velocity="40.0" soft_lower_limit="-1.5" soft_upper_limit="1.5"/>
		<limit effort="0.01" lower="-1" upper="1" velocity="0.5"/>
		<dynamics damping="0.7"/>
	</joint>

	<link name="link3">
		<visual>
			<origin
				xyz="0. 0. 0.072"
				rpy="1.57079632679 0 1.57079632679"
			/>
			<geometry>
				<mesh
					filename="package://snake_robot/snake_description/meshes/servo.stl" scale="0.001 0.001 0.001"/>
			</geometry>
			<material name="Green"/>
		</visual>

		<inertial>
	    <origin xyz="0 0 0.036" rpy="0 0 0"/>
	    <mass value="1"/>
	    <inertia
		  ixx="0.1" ixy="0.0" ixz="0.0"
		  iyy="0.1" iyz="0.0"
		  izz="0.1"/>
	  </inertial>
	</link>

	<joint name="joint3" type="continuous">
		<origin
			xyz="0. 0. 0.072"
			rpy="0. 0. 0."
		/>
		<parent link="link3"/>
		<child link="link4"/>
		<safety_controller k_position="100.0" k_velocity="40.0" soft_lower_limit="-1.5" soft_upper_limit="1.5"/>
		<limit effort="0.01" lower="-1" upper="1" velocity="0.5"/>
		<dynamics damping="0.7"/>
	</joint>

	<link name="link4">
		<visual>
			<origin
				xyz="0. 0. 0.072"
				rpy="1.57079632679 0 0."
			/>
			<geometry>
				<mesh
					filename="package://snake_robot/snake_description/meshes/servo.stl" scale="0.001 0.001 0.001"/>
			</geometry>
			<material name="Green"/>
		</visual>
	</link>

	<transmission name="trans1">
	  <type>transmission_interface/SimpleTransmission</type>
	  <joint name="joint1">
	    <hardwareInterface>hardware_interface/PositionJointInterface</hardwareInterface>
	  </joint>
	  <actuator name="servo1">
	    <mechanicalReduction>1</mechanicalReduction>
	    <hardwareInterface>hardware_interface/PositionJointInterface</hardwareInterface>
	  </actuator>
	</transmission>

	<transmission name="trans2">
	  <type>transmission_interface/SimpleTransmission</type>
	  <joint name="joint2">
	    <hardwareInterface>hardware_interface/PositionJointInterface</hardwareInterface>
	  </joint>
	  <actuator name="servo2">
	    <mechanicalReduction>1</mechanicalReduction>
	    <hardwareInterface>hardware_interface/PositionJointInterface</hardwareInterface>
	  </actuator>
	</transmission>

	<transmission name="trans3">
	  <type>transmission_interface/SimpleTransmission</type>
	  <joint name="joint3">
	    <hardwareInterface>hardware_interface/PositionJointInterface</hardwareInterface>
	  </joint>
	  <actuator name="servo3">
	    <mechanicalReduction>1</mechanicalReduction>
	    <hardwareInterface>hardware_interface/PositionJointInterface</hardwareInterface>
	  </actuator>
	</transmission>
</robot>