<robot name="threeJointsSnake">

  <material name="Blue">
    <color rgba="0.2 0.1 0.8 1.0"/>
  </material>
  <material name="Green">
    <color rgba="0.22 0.32 0.14 1.0"/>
  </material>

	<link name="base_link">
		<visual>
			<origin
				xyz="0. 0. 0."
				rpy="1.57079632679 0 1.57079632679"
			/>
			<geometry>
				<mesh
					filename="package://snake_robot/snake_description/meshes/servo.stl" scale="0.001 0.001 0.001"/>
			</geometry>
			<material name="Blue"/>
		</visual>
	</link>

	<link name="link2">
		<visual>
			<origin
				xyz="0. 0. 0.072"
				rpy="1.57079632679 0 0."
			/>
			<geometry>
				<mesh
					filename="package://snake_robot/snake_description/meshes/servo.stl" scale="0.001 0.001 0.001"/>
			</geometry>
			<material name="Green"/>
		</visual>
	</link>

	<link name="link3">
		<visual>
			<origin
				xyz="0. 0. 0.072"
				rpy="1.57079632679 0 1.57079632679"
			/>
			<geometry>
				<mesh
					filename="package://snake_robot/snake_description/meshes/servo.stl" scale="0.001 0.001 0.001"/>
			</geometry>
			<material name="Green"/>
		</visual>
	</link>

	<joint name="joint1" type="continuous">
		<origin
			xyz="0. 0. 0."
			rpy="0. 0. 0."
		/>
		<parent link="base_link"/>
		<child link="link2"/>
		<safety_controller k_position="100.0" k_velocity="40.0" soft_lower_limit="-1.5" soft_upper_limit="1.5"/>
		<limit effort="0.01" lower="-1" upper="1" velocity="0.5"/>
	</joint>
	<joint name="joint2" type="continuous">
		<origin
			xyz="0. 0. 0.072"
			rpy="0. 0. 1.57079632679"
		/>
		<parent link="link2"/>
		<child link="link3"/>
		<safety_controller k_position="100.0" k_velocity="40.0" soft_lower_limit="-1.5" soft_upper_limit="1.5"/>
		<limit effort="0.01" lower="-1" upper="1" velocity="0.5"/>
	</joint>

	<link name="link4">
		<visual>
			<origin
				xyz="0. 0. 0.072"
				rpy="1.57079632679 0 0."
			/>
			<geometry>
				<mesh
					filename="package://snake_robot/snake_description/meshes/servo.stl" scale="0.001 0.001 0.001"/>
			</geometry>
			<material name="Green"/>
		</visual>
	</link>
	<joint name="joint3" type="continuous">
		<origin
			xyz="0. 0. 0.072"
			rpy="0. 0. 0."
		/>
		<parent link="link3"/>
		<child link="link4"/>
		<safety_controller k_position="100.0" k_velocity="40.0" soft_lower_limit="-1.5" soft_upper_limit="1.5"/>
		<limit effort="0.01" lower="-1" upper="1" velocity="0.5"/>
	</joint>

</robot>